<?xml version="1.0"?>
<robot xmlns:xacro="http://ros.org/wiki/xacro">

  <!-- =============== Constants =============== -->
  <xacro:property name="gripper_type"   value="TRBG-L-B-001"/>
  <xacro:property name="vis_mesh_scale" value="0.01 0.01 0.01"/>
  <xacro:property name="col_mesh_scale" value="0.01 0.01 0.01"/>

  <!-- =============== Load Dependencies =============== -->
  <xacro:include filename="$(find torobo_resources)/urdf/common.xacro" />
  <xacro:include filename="$(find torobo_resources)/urdf/gripper/${gripper_type}/gripper.gazebo.xacro" />

  <!-- =============== Link & Joint =============== -->
  <xacro:macro name="gripper_v0" params="prefix parent use_graspfix *joint_origin">
  
    <joint name="${prefix}gripper_base_joint" type="fixed">
      <xacro:insert_block name="joint_origin"/>
      <parent link="${parent}"/>
      <child link="${prefix}gripper_base"/>
    </joint>

    <link name="${prefix}gripper_base">
      <visual>
        <geometry>
          <mesh filename="package://torobo_resources/meshes/gripper/${gripper_type}/DAE/gripper_base.dae" scale="${vis_mesh_scale}"/>
        </geometry>
        <material name="white"/>
        <origin xyz="0 0 0" rpy="0 0 ${90*M_PI/180}"/>
      </visual>
      <collision>
        <geometry>
          <mesh filename="package://torobo_resources/meshes/gripper/${gripper_type}/STL/gripper_base.stl" scale="${col_mesh_scale}"/>
        </geometry>
        <origin xyz="0 0 0" rpy="0 0 ${90*M_PI/180}"/>
      </collision>
      <inertial>
        <origin xyz="0 -0.007 0.046" rpy="0 0 0"/>
        <mass value="0.76"/>
        <inertia
          ixx="1.104105e-3" ixy="2.054322e-5" ixz="-5.411983e-6"
          iyy="7.765804e-4" iyz="3.247528e-5" izz="6.346240e-4"/>
      </inertial>
    </link>
  
    <link name="${prefix}grasping_frame">
      <visual>
        <origin xyz="0 0 0" rpy="0 0 0"/>
        <geometry>
          <box size="0.02 0.02 0.02" />
        </geometry>
        <material name="clear_color"/>
      </visual>
      <!--
      <collision>
        <origin xyz="0 0 0" rpy="0 0 0"/>
        <geometry>
          <box size="0.02 0.02 0.02" />
        </geometry>
      </collision>
      -->
    </link>
  
    <joint name="${prefix}grasping_frame_joint" type="fixed">
      <parent link="${prefix}gripper_base"/>
      <child link="${prefix}grasping_frame"/>
      <origin xyz="0 0 0.16" rpy="0 0 0"/>
    </joint>
  
    <link name="${prefix}finger_link">
      <visual>
        <origin xyz="0 0 0" rpy="0 0 ${-90*M_PI/180}"/>
        <geometry>
          <mesh filename="package://torobo_resources/meshes/gripper/${gripper_type}/DAE/finger.dae" scale="${vis_mesh_scale}"/>
        </geometry>
        <material name="light_grey"/>
      </visual>
      <collision>
        <origin xyz="0 0 0" rpy="0 0 ${-90*M_PI/180}"/>
        <geometry>
          <mesh filename="package://torobo_resources/meshes/gripper/${gripper_type}/STL/finger.stl" scale="${col_mesh_scale}"/>
        </geometry>
      </collision>
      <inertial>
        <origin xyz="0 0.007 0.046" rpy="0 0 0"/>
        <mass value="0.03"/>
        <inertia
          ixx="0.0004" ixy="0" ixz="0"
          iyy="0.0004" iyz="0" izz="0.0004"/>
      </inertial>
    </link>
  
    <link name="${prefix}mimic_link">
      <visual>
        <origin xyz="0 0 0" rpy="0 0 ${-90*M_PI/180}"/>
        <geometry>
          <mesh filename="package://torobo_resources/meshes/gripper/${gripper_type}/DAE/finger.dae" scale="${vis_mesh_scale}"/>
        </geometry>
        <material name="light_grey"/>
      </visual>
      <collision>
        <origin xyz="0 0 0" rpy="0 0 ${-90*M_PI/180}"/>
        <geometry>
          <mesh filename="package://torobo_resources/meshes/gripper/${gripper_type}/STL/finger.stl" scale="${col_mesh_scale}"/>
        </geometry>
      </collision>
      <inertial>
        <origin xyz="0 -0.007 0.046" rpy="0 0 0"/>
        <mass value="0.03"/>
        <inertia
          ixx="0.0004" ixy="0" ixz="0"
          iyy="0.0004" iyz="0" izz="0.0004"/>
      </inertial>
    </link>
  
    <joint name="${prefix}finger_joint" type="prismatic">
      <parent link="${prefix}mimic_link"/>
      <child link="${prefix}finger_link"/>
      <origin xyz="0 0 0" rpy="0 0 ${180*M_PI/180}"/>
      <axis xyz="0 1 0"/>
      <limit lower="0" upper="0.08" effort="50" velocity="0.5"/>
    </joint>
  
    <joint name="${prefix}mimic_joint" type="prismatic">
      <parent link="${prefix}gripper_base"/>
      <child link="${prefix}mimic_link"/>
      <origin xyz="0 0 0" rpy="0 0 0"/>
      <axis xyz="0 1 0"/>
      <limit lower="0" upper="0.04" effort="50" velocity="0.5"/>
      <mimic joint="${prefix}finger_joint" multiplier="0.5" offset="0.0" />
    </joint>
  
    <!-- Gazebo -->
    <xacro:gripper_gazebo_v0 prefix="${prefix}" use_graspfix="${use_graspfix}"/>
  
    <!-- =============== Transmission =============== -->
    <simple_transmission name="${prefix}finger_joint" reduction="1"/>
    <simple_transmission name="${prefix}mimic_joint" reduction="1"/>

 </xacro:macro>

</robot>
