<?xml version="1.0" encoding="utf-8"?>
<!-- =================================================================================== -->
<!-- |    This document was autogenerated by xacro from load_robot.urdf.xacro          | -->
<!-- |    EDITING THIS FILE BY HAND IS NOT RECOMMENDED                                 | -->
<!-- =================================================================================== -->
<robot name="torobo">
  <material name="black">
    <color rgba="0.0 0.0 0.0 1.0"/>
  </material>
  <material name="blue">
    <color rgba="0.0 0.0 0.8 1.0"/>
  </material>
  <material name="green">
    <color rgba="0.0 0.8 0.0 1.0"/>
  </material>
  <material name="grey">
    <color rgba="0.2 0.2 0.2 1.0"/>
  </material>
  <material name="light_grey">
    <color rgba="0.5 0.5 0.5 1.0"/>
  </material>
  <material name="dark_grey">
    <color rgba="0.3 0.3 0.3 1.0"/>
  </material>
  <material name="orange">
    <color rgba="1.0 0.423529411765 0.0392156862745 1.0"/>
  </material>
  <material name="brown">
    <color rgba="0.870588235294 0.811764705882 0.764705882353 1.0"/>
  </material>
  <material name="red">
    <color rgba="0.8 0.0 0.0 1.0"/>
  </material>
  <material name="white">
    <color rgba="1.0 1.0 1.0 1.0"/>
  </material>
  <material name="clear_color">
    <color rgba="0.5 0.5 0.5 0.1"/>
  </material>
  <!-- ros_control plugin -->
  <gazebo>
    <plugin filename="libtorobo_gazebo_ros_control.so" name="torobo_gazebo_ros_control">
      <robotNamespace>/torobo</robotNamespace>
      <robotSimType>torobo_gazebo_ros_control/DefaultRobotHWSim</robotSimType>
      <legacyModeNS>false</legacyModeNS>
    </plugin>
  </gazebo>
  <!-- world -->
  <link name="world"/>
  <joint name="base_footprint_joint" type="fixed">
    <origin rpy="0 0 0" xyz="0 0 0"/>
    <parent link="world"/>
    <child link="base_footprint"/>
  </joint>
  <link name="base_footprint"/>
  <joint name="base_joint" type="fixed">
    <origin xyz="0 0 0"/>
    <parent link="base_footprint"/>
    <child link="base_link"/>
  </joint>
  <link name="base_link">
    <visual>
      <geometry>
        <mesh filename="package://torobo_resources/meshes/base/TRBB-K-A-001/DAE/base.dae" scale="1.0 1.0 1.0"/>
      </geometry>
      <material name="white"/>
      <origin rpy="0 0 3.14159265359" xyz="0 0 0"/>
    </visual>
    <collision>
      <geometry>
        <mesh filename="package://torobo_resources/meshes/base/TRBB-K-A-001/STL/base.stl" scale="1.0 1.0 1.0"/>
      </geometry>
      <origin rpy="0 0 3.14159265359" xyz="0 0 0"/>
    </collision>
    <inertial>
      <origin xyz="0 0 0"/>
      <mass value="50"/>
      <inertia ixx="1" ixy="0" ixz="0" iyy="1" iyz="0" izz="1"/>
    </inertial>
  </link>
  <joint name="base/joint_tip" type="fixed">
    <parent link="base_link"/>
    <child link="base/link_tip"/>
    <origin rpy="0 0 0" xyz="0 0 0.74"/>
  </joint>
  <link name="base/link_tip"/>
  <joint name="torso/root" type="fixed">
    <origin rpy="0 0 0" xyz="0 0 0"/>
    <parent link="base/link_tip"/>
    <child link="torso/link_0"/>
  </joint>
  <link name="torso/link_0">
    <visual>
      <geometry>
        <mesh filename="package://torobo_resources/meshes/torso/TRBK-T-K-006-2/DAE/link0.dae" scale="1.0 1.0 1.0"/>
      </geometry>
      <material name="white"/>
      <origin xyz="0 0 0"/>
    </visual>
    <collision>
      <geometry>
        <mesh filename="package://torobo_resources/meshes/torso/TRBK-T-K-006-2/STL/link0.stl" scale="1.0 1.0 1.0"/>
      </geometry>
      <origin xyz="0 0 0"/>
    </collision>
    <inertial>
      <origin xyz="0.000 0.000 0.072"/>
      <mass value="4.026904"/>
      <inertia ixx="2.231800e-2" ixy="-9.370000e-8" ixz="6.498320e-5" iyy="2.220438e-2" iyz="6.190000e-8" izz="2.262530e-2"/>
    </inertial>
  </link>
  <joint name="torso/joint_1" type="revolute">
    <parent link="torso/link_0"/>
    <child link="torso/link_1"/>
    <origin rpy="0 0 0" xyz="0.0 0 0.290"/>
    <axis xyz="0 0 1"/>
    <limit effort="110" lower="-2.96705972839" upper="2.96705972839" velocity="2.44346095279"/>
  </joint>
  <link name="torso/link_1">
    <visual>
      <geometry>
        <mesh filename="package://torobo_resources/meshes/torso/TRBK-T-K-006-2/DAE/link1.dae" scale="1.0 1.0 1.0"/>
      </geometry>
      <material name="white"/>
    </visual>
    <collision>
      <geometry>
        <mesh filename="package://torobo_resources/meshes/torso/TRBK-T-K-006-2/STL/link1.stl" scale="1.0 1.0 1.0"/>
      </geometry>
    </collision>
    <inertial>
      <origin xyz="0.000 -0.003 -0.059"/>
      <mass value="6.067716"/>
      <inertia ixx="3.427518e-2" ixy="3.265400e-6" ixz="-8.846100e-6" iyy="3.636420e-2" iyz="1.426545e-3" izz="1.349086e-2"/>
    </inertial>
  </link>
  <joint name="torso/joint_2" type="revolute">
    <parent link="torso/link_1"/>
    <child link="torso/link_2"/>
    <origin rpy="-1.57079632679 0 0" xyz="0 0 0"/>
    <axis xyz="0 0 1"/>
    <limit effort="150" lower="-1.0471975512" upper="1.3962634016" velocity="1.0471975512"/>
  </joint>
  <link name="torso/link_2">
    <visual>
      <geometry>
        <mesh filename="package://torobo_resources/meshes/torso/TRBK-T-K-006-2/DAE/link2.dae" scale="1.0 1.0 1.0"/>
      </geometry>
      <material name="white"/>
    </visual>
    <collision>
      <geometry>
        <mesh filename="package://torobo_resources/meshes/torso/TRBK-T-K-006-2/STL/link2.stl" scale="1.0 1.0 1.0"/>
      </geometry>
    </collision>
    <inertial>
      <origin xyz="-0.004 -0.130 0.003"/>
      <mass value="5.205348"/>
      <inertia ixx="6.642486e-2" ixy="-1.700289e-3" ixz="-6.315480e-5" iyy="1.765227e-2" iyz="-2.463749e-3" izz="6.490475e-2"/>
    </inertial>
  </link>
  <joint name="torso/left_shoulder_joint" type="fixed">
    <parent link="torso/link_2"/>
    <child link="torso/left_shoulder_link"/>
    <origin rpy="0 0 0" xyz="0 -0.285 0.0175"/>
  </joint>
  <link name="torso/left_shoulder_link"/>
  <joint name="torso/right_shoulder_joint" type="fixed">
    <parent link="torso/link_2"/>
    <child link="torso/right_shoulder_link"/>
    <origin rpy="3.14159265359 0 0" xyz="0 -0.285 -0.0175"/>
  </joint>
  <link name="torso/right_shoulder_link"/>
  <joint name="torso/joint_tip" type="fixed">
    <parent link="torso/link_2"/>
    <child link="torso/link_tip"/>
    <origin rpy="1.57079632679 0 0" xyz="0 -0.3945 0"/>
  </joint>
  <link name="torso/link_tip"/>
  <!-- torso_link0 -->
  <gazebo reference="torso/link_0">
    <mu1>0.2</mu1>
    <mu2>0.2</mu2>
  </gazebo>
  <!-- torso_link1 -->
  <gazebo reference="torso/link_1">
    <mu1>0.2</mu1>
    <mu2>0.2</mu2>
  </gazebo>
  <!-- torso_link2 -->
  <gazebo reference="torso/link_2">
    <mu1>0.2</mu1>
    <mu2>0.2</mu2>
  </gazebo>
  <!-- torso_link_tip -->
  <gazebo reference="torso/link_tip">
    <mu1>0.2</mu1>
    <mu2>0.2</mu2>
  </gazebo>
  <transmission name="torso/joint_1_transmission">
    <type>transmission_interface/SimpleTransmission</type>
    <actuator name="torso/joint_1_motor">
      <mechanicalReduction>1</mechanicalReduction>
      <hardwareInterface>hardware_interface/PositionJointInterface</hardwareInterface>
    </actuator>
    <joint name="torso/joint_1">
      <hardwareInterface>hardware_interface/PositionJointInterface</hardwareInterface>
    </joint>
  </transmission>
  <transmission name="torso/joint_2_transmission">
    <type>transmission_interface/SimpleTransmission</type>
    <actuator name="torso/joint_2_motor">
      <mechanicalReduction>1</mechanicalReduction>
      <hardwareInterface>hardware_interface/PositionJointInterface</hardwareInterface>
    </actuator>
    <joint name="torso/joint_2">
      <hardwareInterface>hardware_interface/PositionJointInterface</hardwareInterface>
    </joint>
  </transmission>
  <joint name="head/root" type="fixed">
    <origin rpy="0 0 0" xyz="0 0 0"/>
    <parent link="torso/link_tip"/>
    <child link="head/link_0"/>
  </joint>
  <link name="head/link_0">
    <!-- set dummy inetial param for avoiding gazebo error -->
    <inertial>
      <mass value="1e-5"/>
      <inertia ixx="1e-8" ixy="0" ixz="0" iyy="1e-8" iyz="0" izz="1e-8"/>
    </inertial>
  </link>
  <joint name="head/joint_1" type="revolute">
    <parent link="head/link_0"/>
    <child link="head/link_1"/>
    <origin rpy="0 0 0" xyz="0 0 0"/>
    <axis xyz="0 0 1"/>
    <limit effort="10" lower="-1.57079632679" upper="1.57079632679" velocity="3.14159265359"/>
  </joint>
  <link name="head/link_1">
    <visual>
      <geometry>
        <mesh filename="package://torobo_resources/meshes/head/TRBK-H-K-006-2/DAE/link1.dae" scale="1.0 1.0 1.0"/>
      </geometry>
      <material name="white"/>
    </visual>
    <collision>
      <geometry>
        <mesh filename="package://torobo_resources/meshes/head/TRBK-H-K-006-2/STL/link1.stl" scale="1.0 1.0 1.0"/>
      </geometry>
    </collision>
    <inertial>
      <origin xyz="-0.028 0.002 -0.005"/>
      <mass value="0.681214"/>
      <inertia ixx="4.081641e-4" ixy="8.659100e-6" ixz="1.177480e-4" iyy="6.160155e-4" iyz="-5.357700e-6" izz="5.151108e-4"/>
    </inertial>
  </link>
  <joint name="head/joint_2" type="revolute">
    <parent link="head/link_1"/>
    <child link="head/link_2"/>
    <origin rpy="-1.57079632679 0 0" xyz="-0.035 0 0"/>
    <axis xyz="0 0 1"/>
    <limit effort="10" lower="-0.785398163397" upper="0.785398163397" velocity="3.14159265359"/>
  </joint>
  <link name="head/link_2">
    <visual>
      <geometry>
        <mesh filename="package://torobo_resources/meshes/head/TRBK-H-K-006-2/DAE/link2.dae" scale="1.0 1.0 1.0"/>
      </geometry>
      <material name="white"/>
    </visual>
    <collision>
      <geometry>
        <mesh filename="package://torobo_resources/meshes/head/TRBK-H-K-006-2/STL/link2.stl" scale="1.0 1.0 1.0"/>
      </geometry>
    </collision>
    <inertial>
      <origin xyz="0.034 -0.065 -0.005"/>
      <mass value="0.666210"/>
      <inertia ixx="2.065450e-3" ixy="5.310575e-4" ixz="-9.899790e-5" iyy="2.390063e-3" iyz="1.654064e-4" izz="2.401329e-3"/>
    </inertial>
  </link>
  <joint name="head/joint_tip" type="fixed">
    <parent link="head/link_2"/>
    <child link="head/link_tip"/>
    <origin rpy="0 0 0" xyz="0 0 0"/>
  </joint>
  <link name="head/link_tip"/>
  <!-- Camera -->
  <joint name="head/camera_joint" type="fixed">
    <origin rpy="1.57079632679 0 0" xyz="0.076 -0.105 0"/>
    <parent link="head/link_tip"/>
    <child link="head/camera_link"/>
    <axis xyz="0 1 0"/>
  </joint>
  <link name="head/camera_link">
    <collision>
      <origin rpy="0 0 0" xyz="0 0 0"/>
      <geometry>
        <box size="0.05 0.12 0.02"/>
      </geometry>
    </collision>
    <visual>
      <origin rpy="0 0 0" xyz="0 0 0"/>
      <geometry>
        <box size="0.05 0.12 0.02"/>
      </geometry>
      <material name="black"/>
    </visual>
  </link>
  <joint name="head/camera_color_frame_joint" type="fixed">
    <axis xyz="0 1 0"/>
    <origin rpy="0 0 0" xyz="0.02 0 0"/>
    <parent link="head/camera_link"/>
    <child link="head/camera_color_frame"/>
  </joint>
  <link name="head/camera_color_frame">
    </link>
  <joint name="head/camera_color_optical_frame_joint" type="fixed">
    <axis xyz="0 1 0"/>
    <origin rpy="-1.57079632679 0 -1.57079632679" xyz="0 0 0"/>
    <parent link="head/camera_color_frame"/>
    <child link="head/camera_color_optical_frame"/>
  </joint>
  <link name="head/camera_color_optical_frame">
    </link>
  <!-- camera -->
  <gazebo reference="head/camera_color_frame">
    <material>Gazebo/Black</material>
    <sensor name="head/camera" type="depth">
      <update_rate>30.0</update_rate>
      <camera name="head/camera">
        <horizontal_fov>0.927295218</horizontal_fov>
        <!-- horizontal_fov = 2.0 * arctan(width / 2.0 * focalLength) -->
        <image>
          <width>640</width>
          <height>480</height>
          <format>B8G8R8</format>
        </image>
        <depth>
          <width>640</width>
          <height>480</height>
        </depth>
        <clip>
          <near>0.2</near>
          <far>1.5</far>
        </clip>
      </camera>
      <plugin filename="libgazebo_ros_openni_kinect.so" name="camera_plugin">
        <alwaysOn>true</alwaysOn>
        <updateRate>30.0</updateRate>
        <cameraName>head/camera</cameraName>
        <imageTopicName>color/image_raw</imageTopicName>
        <cameraInfoTopicName>color/camera_info</cameraInfoTopicName>
        <depthImageTopicName>depth/image_raw</depthImageTopicName>
        <depthImageCameraInfoTopicName>depth/camera_info</depthImageCameraInfoTopicName>
        <pointCloudTopicName>depth/points</pointCloudTopicName>
        <frameName>head/camera_color_optical_frame</frameName>
        <pointCloudCutoff>0.2</pointCloudCutoff>
        <pointCloudCutoffMax>1.5</pointCloudCutoffMax>
        <hackBaseline>0.0</hackBaseline>
        <focalLength>640.0</focalLength>
        <CxPrime>0</CxPrime>
        <Cx>0</Cx>
        <!-- gazebo doesn't simulate Cx (rviz does). 0 means that Cx is center of width -->
        <Cy>0</Cy>
        <!-- gazebo doesn't simulate Cy (rviz does). 0 means that Cy is center of width -->
        <distortionK1>0.0</distortionK1>
        <distortionK2>0.0</distortionK2>
        <distortionK3>0.0</distortionK3>
        <distortionT1>0.0</distortionT1>
        <distortionT2>0.0</distortionT2>
      </plugin>
    </sensor>
  </gazebo>
  <!-- head_link0 -->
  <gazebo reference="head/link_0">
    <mu1>0.2</mu1>
    <mu2>0.2</mu2>
  </gazebo>
  <!-- head_link1 -->
  <gazebo reference="head/link_1">
    <mu1>0.2</mu1>
    <mu2>0.2</mu2>
  </gazebo>
  <!-- head_link2 -->
  <gazebo reference="head/link_2">
    <mu1>0.2</mu1>
    <mu2>0.2</mu2>
  </gazebo>
  <!-- head_link_tip -->
  <gazebo reference="head/link_tip">
    <mu1>0.2</mu1>
    <mu2>0.2</mu2>
  </gazebo>
  <transmission name="head/joint_1_transmission">
    <type>transmission_interface/SimpleTransmission</type>
    <actuator name="head/joint_1_motor">
      <mechanicalReduction>1</mechanicalReduction>
      <hardwareInterface>hardware_interface/PositionJointInterface</hardwareInterface>
    </actuator>
    <joint name="head/joint_1">
      <hardwareInterface>hardware_interface/PositionJointInterface</hardwareInterface>
    </joint>
  </transmission>
  <transmission name="head/joint_2_transmission">
    <type>transmission_interface/SimpleTransmission</type>
    <actuator name="head/joint_2_motor">
      <mechanicalReduction>1</mechanicalReduction>
      <hardwareInterface>hardware_interface/PositionJointInterface</hardwareInterface>
    </actuator>
    <joint name="head/joint_2">
      <hardwareInterface>hardware_interface/PositionJointInterface</hardwareInterface>
    </joint>
  </transmission>
  <joint name="left_arm/root" type="fixed">
    <origin rpy="0 0 0" xyz="0 0 0"/>
    <parent link="torso/left_shoulder_link"/>
    <child link="left_arm/link_0"/>
  </joint>
  <link name="left_arm/link_0">
    <visual>
      <geometry>
        <mesh filename="package://torobo_resources/meshes/arm/TRBK-L-K-006-7/DAE/link0.dae" scale="1.0 1.0 1.0"/>
      </geometry>
      <material name="white"/>
    </visual>
    <collision>
      <geometry>
        <mesh filename="package://torobo_resources/meshes/arm/TRBK-L-K-006-7/STL/link0.stl" scale="1.0 1.0 1.0"/>
      </geometry>
    </collision>
    <inertial>
      <origin xyz="0.000 0.000 0.038"/>
      <mass value="1.120865"/>
      <inertia ixx="1.805345e-3" ixy="9.310000e-8" ixz="1.446720e-5" iyy="1.782237e-3" iyz="-1.109000e-7" izz="2.287444e-3"/>
    </inertial>
  </link>
  <joint name="left_arm/joint_1" type="revolute">
    <parent link="left_arm/link_0"/>
    <child link="left_arm/link_1"/>
    <origin rpy="0 3.14159265359 1.57079632679" xyz="0.0 0 0.1775"/>
    <axis xyz="0 0 1"/>
    <limit effort="70" lower="-1.2217304764" upper="4.36332312999" velocity="2.61799387799"/>
  </joint>
  <link name="left_arm/link_1">
    <visual>
      <origin rpy="0 0 0" xyz="0 0 0"/>
      <geometry>
        <mesh filename="package://torobo_resources/meshes/arm/TRBK-L-K-006-7/DAE/link1.dae" scale="1.0 1.0 1.0"/>
      </geometry>
      <material name="white"/>
    </visual>
    <collision>
      <origin rpy="0 0 0" xyz="0 0 0"/>
      <geometry>
        <mesh filename="package://torobo_resources/meshes/arm/TRBK-L-K-006-7/STL/link1.stl" scale="1.0 1.0 1.0"/>
      </geometry>
    </collision>
    <inertial>
      <origin xyz="-0.009 0.006 0.047"/>
      <mass value="2.989853"/>
      <inertia ixx="1.130799e-2" ixy="1.624894e-4" ixz="-1.381978e-3" iyy="1.147156e-2" iyz="7.435181e-4" izz="4.192885e-3"/>
    </inertial>
  </link>
  <joint name="left_arm/joint_2" type="revolute">
    <parent link="left_arm/link_1"/>
    <child link="left_arm/link_2"/>
    <origin rpy="-1.57079632679 3.14159265359 0" xyz="-0.02 0 0"/>
    <axis xyz="0 0 1"/>
    <limit effort="70" lower="-0.610865238198" upper="1.83259571459" velocity="2.61799387799"/>
  </joint>
  <link name="left_arm/link_2">
    <visual>
      <geometry>
        <mesh filename="package://torobo_resources/meshes/arm/TRBK-L-K-006-7/DAE/link2.dae" scale="1.0 1.0 1.0"/>
      </geometry>
      <material name="white"/>
    </visual>
    <collision>
      <geometry>
        <mesh filename="package://torobo_resources/meshes/arm/TRBK-L-K-006-7/STL/link2.stl" scale="1.0 1.0 1.0"/>
      </geometry>
    </collision>
    <inertial>
      <origin xyz="-0.001 -0.047 -0.018"/>
      <mass value="1.780429"/>
      <inertia ixx="6.399320e-3" ixy="-2.318100e-6" ixz="6.069960e-5" iyy="2.899900e-3" iyz="1.390102e-3" izz="6.394456e-3"/>
    </inertial>
  </link>
  <joint name="left_arm/joint_3" type="revolute">
    <parent link="left_arm/link_2"/>
    <child link="left_arm/link_3"/>
    <origin rpy="-1.57079632679 0 0" xyz="0 -0.250 0"/>
    <axis xyz="0 0 1"/>
    <limit effort="35" lower="-1.2217304764" upper="4.36332312999" velocity="3.14159265359"/>
  </joint>
  <link name="left_arm/link_3">
    <visual>
      <geometry>
        <mesh filename="package://torobo_resources/meshes/arm/TRBK-L-K-006-7/DAE/link3.dae" scale="1.0 1.0 1.0"/>
      </geometry>
      <material name="white"/>
    </visual>
    <collision>
      <geometry>
        <mesh filename="package://torobo_resources/meshes/arm/TRBK-L-K-006-7/STL/link3.stl" scale="1.0 1.0 1.0"/>
      </geometry>
    </collision>
    <inertial>
      <origin xyz="0.000 -0.004 0.055"/>
      <mass value="2.384469"/>
      <inertia ixx="9.955916e-3" ixy="1.297000e-7" ixz="5.591000e-7" iyy="9.909352e-3" iyz="-2.861273e-4" izz="2.304165e-3"/>
    </inertial>
  </link>
  <joint name="left_arm/joint_4" type="revolute">
    <parent link="left_arm/link_3"/>
    <child link="left_arm/link_4"/>
    <origin rpy="1.57079632679 0 0" xyz="0 0 0"/>
    <axis xyz="0 0 1"/>
    <limit effort="35" lower="-0.785398163397" upper="2.09439510239" velocity="3.14159265359"/>
  </joint>
  <link name="left_arm/link_4">
    <visual>
      <geometry>
        <mesh filename="package://torobo_resources/meshes/arm/TRBK-L-K-006-7/DAE/link4.dae" scale="1.0 1.0 1.0"/>
      </geometry>
      <material name="white"/>
    </visual>
    <collision>
      <geometry>
        <mesh filename="package://torobo_resources/meshes/arm/TRBK-L-K-006-7/STL/link4.stl" scale="1.0 1.0 1.0"/>
      </geometry>
    </collision>
    <inertial>
      <origin xyz="0.000 -0.081 -0.010"/>
      <mass value="1.731690"/>
      <inertia ixx="7.052932e-3" ixy="4.890000e-7" ixz="6.590000e-8" iyy="1.890919e-3" iyz="1.295489e-3" izz="7.043358e-3"/>
    </inertial>
  </link>
  <joint name="left_arm/joint_5" type="revolute">
    <parent link="left_arm/link_4"/>
    <child link="left_arm/link_5"/>
    <origin rpy="-1.57079632679 -1.57079632679 0" xyz="0 -0.250 0"/>
    <axis xyz="0 0 1"/>
    <limit effort="15" lower="-2.96705972839" upper="2.96705972839" velocity="3.49065850399"/>
  </joint>
  <link name="left_arm/link_5">
    <visual>
      <geometry>
        <mesh filename="package://torobo_resources/meshes/arm/TRBK-L-K-006-7/DAE/link5.dae" scale="1.0 1.0 1.0"/>
      </geometry>
      <material name="white"/>
    </visual>
    <collision>
      <geometry>
        <mesh filename="package://torobo_resources/meshes/arm/TRBK-L-K-006-7/STL/link5.stl" scale="1.0 1.0 1.0"/>
      </geometry>
    </collision>
    <inertial>
      <origin xyz="0.000 -0.022 0.046"/>
      <mass value="0.569666"/>
      <inertia ixx="1.442185e-3" ixy="-1.885700e-6" ixz="-2.154300e-6" iyy="1.241898e-3" iyz="-4.412524e-4" izz="6.598617e-4"/>
    </inertial>
  </link>
  <joint name="left_arm/joint_6" type="revolute">
    <parent link="left_arm/link_5"/>
    <child link="left_arm/link_6"/>
    <origin rpy="1.57079632679 0 0" xyz="0 0 0"/>
    <axis xyz="0 0 1"/>
    <limit effort="15" lower="-1.83259571459" upper="1.57079632679" velocity="3.49065850399"/>
  </joint>
  <link name="left_arm/link_6">
    <visual>
      <geometry>
        <mesh filename="package://torobo_resources/meshes/arm/TRBK-L-K-006-7/DAE/link6.dae" scale="1.0 1.0 1.0"/>
      </geometry>
      <material name="white"/>
    </visual>
    <collision>
      <geometry>
        <mesh filename="package://torobo_resources/meshes/arm/TRBK-L-K-006-7/STL/link6.stl" scale="1.0 1.0 1.0"/>
      </geometry>
    </collision>
    <inertial>
      <origin xyz="0.001 -0.050 0.001"/>
      <mass value="2.061587"/>
      <inertia ixx="6.741245e-3" ixy="7.534230e-5" ixz="1.733300e-6" iyy="2.045197e-3" iyz="-7.481240e-5" izz="6.741057e-3"/>
    </inertial>
  </link>
  <joint name="left_arm/joint_7" type="revolute">
    <parent link="left_arm/link_6"/>
    <child link="left_arm/link_7"/>
    <origin rpy="1.57079632679 0.0 -1.57079632679" xyz="0.063 -0.100 0"/>
    <axis xyz="0 0 1"/>
    <limit effort="15" lower="-2.96705972839" upper="2.96705972839" velocity="3.49065850399"/>
  </joint>
  <link name="left_arm/link_7">
    <visual>
      <geometry>
        <mesh filename="package://torobo_resources/meshes/arm/TRBK-L-K-006-7/DAE/link7.dae" scale="1.0 1.0 1.0"/>
      </geometry>
      <material name="white"/>
    </visual>
    <collision>
      <geometry>
        <mesh filename="package://torobo_resources/meshes/arm/TRBK-L-K-006-7/STL/link7.stl" scale="1.0 1.0 1.0"/>
      </geometry>
    </collision>
    <inertial>
      <origin xyz="0.001 0.000 0.018"/>
      <mass value="0.269758"/>
      <inertia ixx="1.501149e-4" ixy="5.190000e-8" ixz="6.478000e-7" iyy="1.521761e-4" iyz="1.320000e-8" izz="2.083653e-4"/>
    </inertial>
  </link>
  <joint name="left_arm/joint_tip" type="fixed">
    <parent link="left_arm/link_7"/>
    <child link="left_arm/link_tip"/>
    <origin rpy="3.14159265359 0 0" xyz="0 0 0"/>
  </joint>
  <link name="left_arm/link_tip"/>
  <!-- Link1 -->
  <gazebo reference="left_arm/link_1">
    <mu1>0.2</mu1>
    <mu2>0.2</mu2>
  </gazebo>
  <!-- Link2 -->
  <gazebo reference="left_arm/link_2">
    <mu1>0.2</mu1>
    <mu2>0.2</mu2>
  </gazebo>
  <!-- Link3 -->
  <gazebo reference="left_arm/link_3">
    <mu1>0.2</mu1>
    <mu2>0.2</mu2>
  </gazebo>
  <!-- Link4 -->
  <gazebo reference="left_arm/link_4">
    <mu1>0.2</mu1>
    <mu2>0.2</mu2>
  </gazebo>
  <!-- Link5 -->
  <gazebo reference="left_arm/link_5">
    <mu1>0.2</mu1>
    <mu2>0.2</mu2>
  </gazebo>
  <!-- Link6 -->
  <gazebo reference="left_arm/link_6">
    <mu1>0.2</mu1>
    <mu2>0.2</mu2>
  </gazebo>
  <!-- Link7 -->
  <gazebo reference="left_arm/link_7">
    <mu1>0.2</mu1>
    <mu2>0.2</mu2>
  </gazebo>
  <!-- EE Link -->
  <gazebo reference="left_arm/link_tip">
    <mu1>0.2</mu1>
    <mu2>0.2</mu2>
  </gazebo>
  <transmission name="left_arm/joint_1_transmission">
    <type>transmission_interface/SimpleTransmission</type>
    <actuator name="left_arm/joint_1_motor">
      <mechanicalReduction>1</mechanicalReduction>
      <hardwareInterface>hardware_interface/PositionJointInterface</hardwareInterface>
    </actuator>
    <joint name="left_arm/joint_1">
      <hardwareInterface>hardware_interface/PositionJointInterface</hardwareInterface>
    </joint>
  </transmission>
  <transmission name="left_arm/joint_2_transmission">
    <type>transmission_interface/SimpleTransmission</type>
    <actuator name="left_arm/joint_2_motor">
      <mechanicalReduction>1</mechanicalReduction>
      <hardwareInterface>hardware_interface/PositionJointInterface</hardwareInterface>
    </actuator>
    <joint name="left_arm/joint_2">
      <hardwareInterface>hardware_interface/PositionJointInterface</hardwareInterface>
    </joint>
  </transmission>
  <transmission name="left_arm/joint_3_transmission">
    <type>transmission_interface/SimpleTransmission</type>
    <actuator name="left_arm/joint_3_motor">
      <mechanicalReduction>1</mechanicalReduction>
      <hardwareInterface>hardware_interface/PositionJointInterface</hardwareInterface>
    </actuator>
    <joint name="left_arm/joint_3">
      <hardwareInterface>hardware_interface/PositionJointInterface</hardwareInterface>
    </joint>
  </transmission>
  <transmission name="left_arm/joint_4_transmission">
    <type>transmission_interface/SimpleTransmission</type>
    <actuator name="left_arm/joint_4_motor">
      <mechanicalReduction>1</mechanicalReduction>
      <hardwareInterface>hardware_interface/PositionJointInterface</hardwareInterface>
    </actuator>
    <joint name="left_arm/joint_4">
      <hardwareInterface>hardware_interface/PositionJointInterface</hardwareInterface>
    </joint>
  </transmission>
  <transmission name="left_arm/joint_5_transmission">
    <type>transmission_interface/SimpleTransmission</type>
    <actuator name="left_arm/joint_5_motor">
      <mechanicalReduction>1</mechanicalReduction>
      <hardwareInterface>hardware_interface/PositionJointInterface</hardwareInterface>
    </actuator>
    <joint name="left_arm/joint_5">
      <hardwareInterface>hardware_interface/PositionJointInterface</hardwareInterface>
    </joint>
  </transmission>
  <transmission name="left_arm/joint_6_transmission">
    <type>transmission_interface/SimpleTransmission</type>
    <actuator name="left_arm/joint_6_motor">
      <mechanicalReduction>1</mechanicalReduction>
      <hardwareInterface>hardware_interface/PositionJointInterface</hardwareInterface>
    </actuator>
    <joint name="left_arm/joint_6">
      <hardwareInterface>hardware_interface/PositionJointInterface</hardwareInterface>
    </joint>
  </transmission>
  <transmission name="left_arm/joint_7_transmission">
    <type>transmission_interface/SimpleTransmission</type>
    <actuator name="left_arm/joint_7_motor">
      <mechanicalReduction>1</mechanicalReduction>
      <hardwareInterface>hardware_interface/PositionJointInterface</hardwareInterface>
    </actuator>
    <joint name="left_arm/joint_7">
      <hardwareInterface>hardware_interface/PositionJointInterface</hardwareInterface>
    </joint>
  </transmission>
  <joint name="right_arm/root" type="fixed">
    <origin rpy="0 0 0" xyz="0 0 0"/>
    <parent link="torso/right_shoulder_link"/>
    <child link="right_arm/link_0"/>
  </joint>
  <link name="right_arm/link_0">
    <visual>
      <geometry>
        <mesh filename="package://torobo_resources/meshes/arm/TRBK-R-K-006-7/DAE/link0.dae" scale="1.0 1.0 1.0"/>
      </geometry>
      <material name="white"/>
    </visual>
    <collision>
      <geometry>
        <mesh filename="package://torobo_resources/meshes/arm/TRBK-R-K-006-7/STL/link0.stl" scale="1.0 1.0 1.0"/>
      </geometry>
    </collision>
    <inertial>
      <origin xyz="0.000 0.000 0.038"/>
      <mass value="1.120865"/>
      <inertia ixx="1.805345e-3" ixy="-9.310000e-8" ixz="1.446720e-5" iyy="1.782237e-3" iyz="1.109000e-7" izz="2.287444e-3"/>
    </inertial>
  </link>
  <joint name="right_arm/joint_1" type="revolute">
    <parent link="right_arm/link_0"/>
    <child link="right_arm/link_1"/>
    <origin rpy="0 0 -1.57079632679" xyz="0.0 0 0.1775"/>
    <axis xyz="0 0 1"/>
    <limit effort="70" lower="-1.2217304764" upper="4.36332312999" velocity="2.61799387799"/>
  </joint>
  <link name="right_arm/link_1">
    <visual>
      <geometry>
        <mesh filename="package://torobo_resources/meshes/arm/TRBK-R-K-006-7/DAE/link1.dae" scale="1.0 1.0 1.0"/>
      </geometry>
      <material name="white"/>
    </visual>
    <collision>
      <geometry>
        <mesh filename="package://torobo_resources/meshes/arm/TRBK-R-K-006-7/STL/link1.stl" scale="1.0 1.0 1.0"/>
      </geometry>
    </collision>
    <inertial>
      <origin xyz="0.009 -0.006 -0.047"/>
      <mass value="2.989853"/>
      <inertia ixx="1.130799e-2" ixy="1.624894e-4" ixz="-1.381978e-3" iyy="1.147156e-2" iyz="7.435181e-4" izz="4.192885e-3"/>
    </inertial>
  </link>
  <joint name="right_arm/joint_2" type="revolute">
    <parent link="right_arm/link_1"/>
    <child link="right_arm/link_2"/>
    <origin rpy="-1.57079632679 0 0" xyz="0.02 0 0"/>
    <axis xyz="0 0 1"/>
    <limit effort="70" lower="-0.610865238198" upper="1.83259571459" velocity="2.61799387799"/>
  </joint>
  <link name="right_arm/link_2">
    <visual>
      <geometry>
        <mesh filename="package://torobo_resources/meshes/arm/TRBK-R-K-006-7/DAE/link2.dae" scale="1.0 1.0 1.0"/>
      </geometry>
      <material name="white"/>
    </visual>
    <collision>
      <geometry>
        <mesh filename="package://torobo_resources/meshes/arm/TRBK-R-K-006-7/STL/link2.stl" scale="1.0 1.0 1.0"/>
      </geometry>
    </collision>
    <inertial>
      <origin xyz="-0.001 -0.047 0.018"/>
      <mass value="1.780429"/>
      <inertia ixx="6.399320e-3" ixy="-2.318100e-6" ixz="-6.069960e-5" iyy="2.899900e-3" iyz="-1.390102e-3" izz="6.394456e-3"/>
    </inertial>
  </link>
  <joint name="right_arm/joint_3" type="revolute">
    <parent link="right_arm/link_2"/>
    <child link="right_arm/link_3"/>
    <origin rpy="1.57079632679 0 0" xyz="0 -0.250 0"/>
    <axis xyz="0 0 1"/>
    <limit effort="35" lower="-1.2217304764" upper="4.36332312999" velocity="3.14159265359"/>
  </joint>
  <link name="right_arm/link_3">
    <visual>
      <geometry>
        <mesh filename="package://torobo_resources/meshes/arm/TRBK-R-K-006-7/DAE/link3.dae" scale="1.0 1.0 1.0"/>
      </geometry>
      <material name="white"/>
    </visual>
    <collision>
      <geometry>
        <mesh filename="package://torobo_resources/meshes/arm/TRBK-R-K-006-7/STL/link3.stl" scale="1.0 1.0 1.0"/>
      </geometry>
    </collision>
    <inertial>
      <origin xyz="0.000 -0.004 -0.055"/>
      <mass value="2.384469"/>
      <inertia ixx="9.955916e-3" ixy="-1.297000e-7" ixz="5.591000e-7" iyy="9.909352e-3" iyz="2.861273e-4" izz="2.304165e-3"/>
    </inertial>
  </link>
  <joint name="right_arm/joint_4" type="revolute">
    <parent link="right_arm/link_3"/>
    <child link="right_arm/link_4"/>
    <origin rpy="-1.57079632679 0 0" xyz="0 0 0"/>
    <axis xyz="0 0 1"/>
    <limit effort="35" lower="-0.785398163397" upper="2.09439510239" velocity="3.14159265359"/>
  </joint>
  <link name="right_arm/link_4">
    <visual>
      <geometry>
        <mesh filename="package://torobo_resources/meshes/arm/TRBK-R-K-006-7/DAE/link4.dae" scale="1.0 1.0 1.0"/>
      </geometry>
      <material name="white"/>
    </visual>
    <collision>
      <geometry>
        <mesh filename="package://torobo_resources/meshes/arm/TRBK-R-K-006-7/STL/link4.stl" scale="1.0 1.0 1.0"/>
      </geometry>
    </collision>
    <inertial>
      <origin xyz="0.000 -0.081 0.010"/>
      <mass value="1.731690"/>
      <inertia ixx="7.052932e-3" ixy="-4.890000e-7" ixz="6.590000e-8" iyy="1.890919e-3" iyz="-1.295489e-3" izz="7.043358e-3"/>
    </inertial>
  </link>
  <joint name="right_arm/joint_5" type="revolute">
    <parent link="right_arm/link_4"/>
    <child link="right_arm/link_5"/>
    <origin rpy="1.57079632679 1.57079632679 0" xyz="0 -0.250 0"/>
    <axis xyz="0 0 1"/>
    <limit effort="15" lower="-2.96705972839" upper="2.96705972839" velocity="3.49065850399"/>
  </joint>
  <link name="right_arm/link_5">
    <visual>
      <geometry>
        <mesh filename="package://torobo_resources/meshes/arm/TRBK-R-K-006-7/DAE/link5.dae" scale="1.0 1.0 1.0"/>
      </geometry>
      <material name="white"/>
    </visual>
    <collision>
      <geometry>
        <mesh filename="package://torobo_resources/meshes/arm/TRBK-R-K-006-7/STL/link5.stl" scale="1.0 1.0 1.0"/>
      </geometry>
    </collision>
    <inertial>
      <origin xyz="0.000 -0.022 -0.046"/>
      <mass value="0.569666"/>
      <inertia ixx="1.442185e-3" ixy="-1.885700e-6" ixz="2.154300e-6" iyy="1.241898e-3" iyz="4.412524e-4" izz="6.598617e-4"/>
    </inertial>
  </link>
  <joint name="right_arm/joint_6" type="revolute">
    <parent link="right_arm/link_5"/>
    <child link="right_arm/link_6"/>
    <origin rpy="-1.57079632679 0 0" xyz="0 0 0"/>
    <axis xyz="0 0 1"/>
    <limit effort="15" lower="-1.83259571459" upper="1.57079632679" velocity="3.49065850399"/>
  </joint>
  <link name="right_arm/link_6">
    <visual>
      <geometry>
        <mesh filename="package://torobo_resources/meshes/arm/TRBK-R-K-006-7/DAE/link6.dae" scale="1.0 1.0 1.0"/>
      </geometry>
      <material name="white"/>
    </visual>
    <collision>
      <geometry>
        <mesh filename="package://torobo_resources/meshes/arm/TRBK-R-K-006-7/STL/link6.stl" scale="1.0 1.0 1.0"/>
      </geometry>
    </collision>
    <inertial>
      <origin xyz="0.001 -0.050 -0.001"/>
      <mass value="2.061587"/>
      <inertia ixx="6.741245e-3" ixy="7.534230e-5" ixz="-1.733300e-6" iyy="2.045197e-3" iyz="7.481240e-5" izz="6.741057e-3"/>
    </inertial>
  </link>
  <joint name="right_arm/joint_7" type="revolute">
    <parent link="right_arm/link_6"/>
    <child link="right_arm/link_7"/>
    <origin rpy="1.57079632679 0 1.57079632679" xyz="0.063 -0.100 0"/>
    <axis xyz="0 0 1"/>
    <limit effort="15" lower="-2.96705972839" upper="2.96705972839" velocity="3.49065850399"/>
  </joint>
  <link name="right_arm/link_7">
    <visual>
      <geometry>
        <mesh filename="package://torobo_resources/meshes/arm/TRBK-R-K-006-7/DAE/link7.dae" scale="1.0 1.0 1.0"/>
      </geometry>
      <material name="white"/>
    </visual>
    <collision>
      <geometry>
        <mesh filename="package://torobo_resources/meshes/arm/TRBK-R-K-006-7/STL/link7.stl" scale="1.0 1.0 1.0"/>
      </geometry>
    </collision>
    <inertial>
      <origin xyz="-0.001 0.000 -0.018"/>
      <mass value="0.269758"/>
      <inertia ixx="1.501149e-4" ixy="5.190000e-8" ixz="6.478000e-7" iyy="1.521761e-4" iyz="1.320000e-8" izz="2.083653e-4"/>
    </inertial>
  </link>
  <joint name="right_arm/joint_tip" type="fixed">
    <parent link="right_arm/link_7"/>
    <child link="right_arm/link_tip"/>
    <origin rpy="0 0 0" xyz="0 0 0"/>
  </joint>
  <link name="right_arm/link_tip"/>
  <!-- Link1 -->
  <gazebo reference="right_arm/link_1">
    <mu1>0.2</mu1>
    <mu2>0.2</mu2>
  </gazebo>
  <!-- Link2 -->
  <gazebo reference="right_arm/link_2">
    <mu1>0.2</mu1>
    <mu2>0.2</mu2>
  </gazebo>
  <!-- Link3 -->
  <gazebo reference="right_arm/link_3">
    <mu1>0.2</mu1>
    <mu2>0.2</mu2>
  </gazebo>
  <!-- Link4 -->
  <gazebo reference="right_arm/link_4">
    <mu1>0.2</mu1>
    <mu2>0.2</mu2>
  </gazebo>
  <!-- Link5 -->
  <gazebo reference="right_arm/link_5">
    <mu1>0.2</mu1>
    <mu2>0.2</mu2>
  </gazebo>
  <!-- Link6 -->
  <gazebo reference="right_arm/link_6">
    <mu1>0.2</mu1>
    <mu2>0.2</mu2>
  </gazebo>
  <!-- Link7 -->
  <gazebo reference="right_arm/link_7">
    <mu1>0.2</mu1>
    <mu2>0.2</mu2>
  </gazebo>
  <!-- EE Link -->
  <gazebo reference="right_arm/link_tip">
    <mu1>0.2</mu1>
    <mu2>0.2</mu2>
  </gazebo>
  <transmission name="right_arm/joint_1_transmission">
    <type>transmission_interface/SimpleTransmission</type>
    <actuator name="right_arm/joint_1_motor">
      <mechanicalReduction>1</mechanicalReduction>
      <hardwareInterface>hardware_interface/PositionJointInterface</hardwareInterface>
    </actuator>
    <joint name="right_arm/joint_1">
      <hardwareInterface>hardware_interface/PositionJointInterface</hardwareInterface>
    </joint>
  </transmission>
  <transmission name="right_arm/joint_2_transmission">
    <type>transmission_interface/SimpleTransmission</type>
    <actuator name="right_arm/joint_2_motor">
      <mechanicalReduction>1</mechanicalReduction>
      <hardwareInterface>hardware_interface/PositionJointInterface</hardwareInterface>
    </actuator>
    <joint name="right_arm/joint_2">
      <hardwareInterface>hardware_interface/PositionJointInterface</hardwareInterface>
    </joint>
  </transmission>
  <transmission name="right_arm/joint_3_transmission">
    <type>transmission_interface/SimpleTransmission</type>
    <actuator name="right_arm/joint_3_motor">
      <mechanicalReduction>1</mechanicalReduction>
      <hardwareInterface>hardware_interface/PositionJointInterface</hardwareInterface>
    </actuator>
    <joint name="right_arm/joint_3">
      <hardwareInterface>hardware_interface/PositionJointInterface</hardwareInterface>
    </joint>
  </transmission>
  <transmission name="right_arm/joint_4_transmission">
    <type>transmission_interface/SimpleTransmission</type>
    <actuator name="right_arm/joint_4_motor">
      <mechanicalReduction>1</mechanicalReduction>
      <hardwareInterface>hardware_interface/PositionJointInterface</hardwareInterface>
    </actuator>
    <joint name="right_arm/joint_4">
      <hardwareInterface>hardware_interface/PositionJointInterface</hardwareInterface>
    </joint>
  </transmission>
  <transmission name="right_arm/joint_5_transmission">
    <type>transmission_interface/SimpleTransmission</type>
    <actuator name="right_arm/joint_5_motor">
      <mechanicalReduction>1</mechanicalReduction>
      <hardwareInterface>hardware_interface/PositionJointInterface</hardwareInterface>
    </actuator>
    <joint name="right_arm/joint_5">
      <hardwareInterface>hardware_interface/PositionJointInterface</hardwareInterface>
    </joint>
  </transmission>
  <transmission name="right_arm/joint_6_transmission">
    <type>transmission_interface/SimpleTransmission</type>
    <actuator name="right_arm/joint_6_motor">
      <mechanicalReduction>1</mechanicalReduction>
      <hardwareInterface>hardware_interface/PositionJointInterface</hardwareInterface>
    </actuator>
    <joint name="right_arm/joint_6">
      <hardwareInterface>hardware_interface/PositionJointInterface</hardwareInterface>
    </joint>
  </transmission>
  <transmission name="right_arm/joint_7_transmission">
    <type>transmission_interface/SimpleTransmission</type>
    <actuator name="right_arm/joint_7_motor">
      <mechanicalReduction>1</mechanicalReduction>
      <hardwareInterface>hardware_interface/PositionJointInterface</hardwareInterface>
    </actuator>
    <joint name="right_arm/joint_7">
      <hardwareInterface>hardware_interface/PositionJointInterface</hardwareInterface>
    </joint>
  </transmission>
  <joint name="left_gripper/gripper_base_joint" type="fixed">
    <origin rpy="0 0 0" xyz="0 0 0"/>
    <parent link="left_arm/link_tip"/>
    <child link="left_gripper/gripper_base"/>
  </joint>
  <link name="left_gripper/gripper_base">
    <visual>
      <geometry>
        <mesh filename="package://torobo_resources/meshes/gripper/TRBG-L-B-001/DAE/gripper_base.dae" scale="0.01 0.01 0.01"/>
      </geometry>
      <material name="white"/>
      <origin rpy="0 0 1.57079632679" xyz="0 0 0"/>
    </visual>
    <collision>
      <geometry>
        <mesh filename="package://torobo_resources/meshes/gripper/TRBG-L-B-001/STL/gripper_base.stl" scale="0.01 0.01 0.01"/>
      </geometry>
      <origin rpy="0 0 1.57079632679" xyz="0 0 0"/>
    </collision>
    <inertial>
      <origin rpy="0 0 0" xyz="0 -0.007 0.046"/>
      <mass value="0.76"/>
      <inertia ixx="1.104105e-3" ixy="2.054322e-5" ixz="-5.411983e-6" iyy="7.765804e-4" iyz="3.247528e-5" izz="6.346240e-4"/>
    </inertial>
  </link>
  <link name="left_gripper/grasping_frame">
    <visual>
      <origin rpy="0 0 0" xyz="0 0 0"/>
      <geometry>
        <box size="0.02 0.02 0.02"/>
      </geometry>
      <material name="clear_color"/>
    </visual>
    <!--
      <collision>
        <origin xyz="0 0 0" rpy="0 0 0"/>
        <geometry>
          <box size="0.02 0.02 0.02" />
        </geometry>
      </collision>
      -->
  </link>
  <joint name="left_gripper/grasping_frame_joint" type="fixed">
    <parent link="left_gripper/gripper_base"/>
    <child link="left_gripper/grasping_frame"/>
    <origin rpy="0 0 0" xyz="0 0 0.16"/>
  </joint>
  <link name="left_gripper/finger_link">
    <visual>
      <origin rpy="0 0 -1.57079632679" xyz="0 0 0"/>
      <geometry>
        <mesh filename="package://torobo_resources/meshes/gripper/TRBG-L-B-001/DAE/finger.dae" scale="0.01 0.01 0.01"/>
      </geometry>
      <material name="light_grey"/>
    </visual>
    <collision>
      <origin rpy="0 0 -1.57079632679" xyz="0 0 0"/>
      <geometry>
        <mesh filename="package://torobo_resources/meshes/gripper/TRBG-L-B-001/STL/finger.stl" scale="0.01 0.01 0.01"/>
      </geometry>
    </collision>
    <inertial>
      <origin rpy="0 0 0" xyz="0 0.007 0.046"/>
      <mass value="0.03"/>
      <inertia ixx="0.0004" ixy="0" ixz="0" iyy="0.0004" iyz="0" izz="0.0004"/>
    </inertial>
  </link>
  <link name="left_gripper/mimic_link">
    <visual>
      <origin rpy="0 0 -1.57079632679" xyz="0 0 0"/>
      <geometry>
        <mesh filename="package://torobo_resources/meshes/gripper/TRBG-L-B-001/DAE/finger.dae" scale="0.01 0.01 0.01"/>
      </geometry>
      <material name="light_grey"/>
    </visual>
    <collision>
      <origin rpy="0 0 -1.57079632679" xyz="0 0 0"/>
      <geometry>
        <mesh filename="package://torobo_resources/meshes/gripper/TRBG-L-B-001/STL/finger.stl" scale="0.01 0.01 0.01"/>
      </geometry>
    </collision>
    <inertial>
      <origin rpy="0 0 0" xyz="0 -0.007 0.046"/>
      <mass value="0.03"/>
      <inertia ixx="0.0004" ixy="0" ixz="0" iyy="0.0004" iyz="0" izz="0.0004"/>
    </inertial>
  </link>
  <joint name="left_gripper/finger_joint" type="prismatic">
    <parent link="left_gripper/mimic_link"/>
    <child link="left_gripper/finger_link"/>
    <origin rpy="0 0 3.14159265359" xyz="0 0 0"/>
    <axis xyz="0 1 0"/>
    <limit effort="50" lower="0" upper="0.08" velocity="0.5"/>
  </joint>
  <joint name="left_gripper/mimic_joint" type="prismatic">
    <parent link="left_gripper/gripper_base"/>
    <child link="left_gripper/mimic_link"/>
    <origin rpy="0 0 0" xyz="0 0 0"/>
    <axis xyz="0 1 0"/>
    <limit effort="50" lower="0" upper="0.04" velocity="0.5"/>
    <mimic joint="left_gripper/finger_joint" multiplier="0.5" offset="0.0"/>
  </joint>
  <!-- ros_control plugin -->
  <gazebo>
  </gazebo>
  <!-- grasping_frame -->
  <gazebo reference="left_gripper/grasping_frame">
    <mu1>0.2</mu1>
    <mu2>0.2</mu2>
  </gazebo>
  <!-- gripper_base -->
  <gazebo reference="left_gripper/gripper_base">
    <mu1>0.2</mu1>
    <mu2>0.2</mu2>
  </gazebo>
  <!-- right_finger -->
  <gazebo reference="left_gripper/finger_joint">
    <mu1>0.2</mu1>
    <mu2>0.2</mu2>
  </gazebo>
  <!-- left_finger -->
  <gazebo reference="left_gripper/mimic_joint">
    <mu1>0.2</mu1>
    <mu2>0.2</mu2>
  </gazebo>
  <transmission name="left_gripper/finger_joint_transmission">
    <type>transmission_interface/SimpleTransmission</type>
    <actuator name="left_gripper/finger_joint_motor">
      <mechanicalReduction>1</mechanicalReduction>
      <hardwareInterface>hardware_interface/PositionJointInterface</hardwareInterface>
    </actuator>
    <joint name="left_gripper/finger_joint">
      <hardwareInterface>hardware_interface/PositionJointInterface</hardwareInterface>
    </joint>
  </transmission>
  <transmission name="left_gripper/mimic_joint_transmission">
    <type>transmission_interface/SimpleTransmission</type>
    <actuator name="left_gripper/mimic_joint_motor">
      <mechanicalReduction>1</mechanicalReduction>
      <hardwareInterface>hardware_interface/PositionJointInterface</hardwareInterface>
    </actuator>
    <joint name="left_gripper/mimic_joint">
      <hardwareInterface>hardware_interface/PositionJointInterface</hardwareInterface>
    </joint>
  </transmission>
  <joint name="right_gripper/gripper_base_joint" type="fixed">
    <origin rpy="0 0 0" xyz="0 0 0"/>
    <parent link="right_arm/link_tip"/>
    <child link="right_gripper/gripper_base"/>
  </joint>
  <link name="right_gripper/gripper_base">
    <visual>
      <geometry>
        <mesh filename="package://torobo_resources/meshes/gripper/TRBG-L-B-001/DAE/gripper_base.dae" scale="0.01 0.01 0.01"/>
      </geometry>
      <material name="white"/>
      <origin rpy="0 0 1.57079632679" xyz="0 0 0"/>
    </visual>
    <collision>
      <geometry>
        <mesh filename="package://torobo_resources/meshes/gripper/TRBG-L-B-001/STL/gripper_base.stl" scale="0.01 0.01 0.01"/>
      </geometry>
      <origin rpy="0 0 1.57079632679" xyz="0 0 0"/>
    </collision>
    <inertial>
      <origin rpy="0 0 0" xyz="0 -0.007 0.046"/>
      <mass value="0.76"/>
      <inertia ixx="1.104105e-3" ixy="2.054322e-5" ixz="-5.411983e-6" iyy="7.765804e-4" iyz="3.247528e-5" izz="6.346240e-4"/>
    </inertial>
  </link>
  <link name="right_gripper/grasping_frame">
    <visual>
      <origin rpy="0 0 0" xyz="0 0 0"/>
      <geometry>
        <box size="0.02 0.02 0.02"/>
      </geometry>
      <material name="clear_color"/>
    </visual>
    <!--
      <collision>
        <origin xyz="0 0 0" rpy="0 0 0"/>
        <geometry>
          <box size="0.02 0.02 0.02" />
        </geometry>
      </collision>
      -->
  </link>
  <joint name="right_gripper/grasping_frame_joint" type="fixed">
    <parent link="right_gripper/gripper_base"/>
    <child link="right_gripper/grasping_frame"/>
    <origin rpy="0 0 0" xyz="0 0 0.16"/>
  </joint>
  <link name="right_gripper/finger_link">
    <visual>
      <origin rpy="0 0 -1.57079632679" xyz="0 0 0"/>
      <geometry>
        <mesh filename="package://torobo_resources/meshes/gripper/TRBG-L-B-001/DAE/finger.dae" scale="0.01 0.01 0.01"/>
      </geometry>
      <material name="light_grey"/>
    </visual>
    <collision>
      <origin rpy="0 0 -1.57079632679" xyz="0 0 0"/>
      <geometry>
        <mesh filename="package://torobo_resources/meshes/gripper/TRBG-L-B-001/STL/finger.stl" scale="0.01 0.01 0.01"/>
      </geometry>
    </collision>
    <inertial>
      <origin rpy="0 0 0" xyz="0 0.007 0.046"/>
      <mass value="0.03"/>
      <inertia ixx="0.0004" ixy="0" ixz="0" iyy="0.0004" iyz="0" izz="0.0004"/>
    </inertial>
  </link>
  <link name="right_gripper/mimic_link">
    <visual>
      <origin rpy="0 0 -1.57079632679" xyz="0 0 0"/>
      <geometry>
        <mesh filename="package://torobo_resources/meshes/gripper/TRBG-L-B-001/DAE/finger.dae" scale="0.01 0.01 0.01"/>
      </geometry>
      <material name="light_grey"/>
    </visual>
    <collision>
      <origin rpy="0 0 -1.57079632679" xyz="0 0 0"/>
      <geometry>
        <mesh filename="package://torobo_resources/meshes/gripper/TRBG-L-B-001/STL/finger.stl" scale="0.01 0.01 0.01"/>
      </geometry>
    </collision>
    <inertial>
      <origin rpy="0 0 0" xyz="0 -0.007 0.046"/>
      <mass value="0.03"/>
      <inertia ixx="0.0004" ixy="0" ixz="0" iyy="0.0004" iyz="0" izz="0.0004"/>
    </inertial>
  </link>
  <joint name="right_gripper/finger_joint" type="prismatic">
    <parent link="right_gripper/mimic_link"/>
    <child link="right_gripper/finger_link"/>
    <origin rpy="0 0 3.14159265359" xyz="0 0 0"/>
    <axis xyz="0 1 0"/>
    <limit effort="50" lower="0" upper="0.08" velocity="0.5"/>
  </joint>
  <joint name="right_gripper/mimic_joint" type="prismatic">
    <parent link="right_gripper/gripper_base"/>
    <child link="right_gripper/mimic_link"/>
    <origin rpy="0 0 0" xyz="0 0 0"/>
    <axis xyz="0 1 0"/>
    <limit effort="50" lower="0" upper="0.04" velocity="0.5"/>
    <mimic joint="right_gripper/finger_joint" multiplier="0.5" offset="0.0"/>
  </joint>
  <!-- ros_control plugin -->
  <gazebo>
  </gazebo>
  <!-- grasping_frame -->
  <gazebo reference="right_gripper/grasping_frame">
    <mu1>0.2</mu1>
    <mu2>0.2</mu2>
  </gazebo>
  <!-- gripper_base -->
  <gazebo reference="right_gripper/gripper_base">
    <mu1>0.2</mu1>
    <mu2>0.2</mu2>
  </gazebo>
  <!-- right_finger -->
  <gazebo reference="right_gripper/finger_joint">
    <mu1>0.2</mu1>
    <mu2>0.2</mu2>
  </gazebo>
  <!-- left_finger -->
  <gazebo reference="right_gripper/mimic_joint">
    <mu1>0.2</mu1>
    <mu2>0.2</mu2>
  </gazebo>
  <transmission name="right_gripper/finger_joint_transmission">
    <type>transmission_interface/SimpleTransmission</type>
    <actuator name="right_gripper/finger_joint_motor">
      <mechanicalReduction>1</mechanicalReduction>
      <hardwareInterface>hardware_interface/PositionJointInterface</hardwareInterface>
    </actuator>
    <joint name="right_gripper/finger_joint">
      <hardwareInterface>hardware_interface/PositionJointInterface</hardwareInterface>
    </joint>
  </transmission>
  <transmission name="right_gripper/mimic_joint_transmission">
    <type>transmission_interface/SimpleTransmission</type>
    <actuator name="right_gripper/mimic_joint_motor">
      <mechanicalReduction>1</mechanicalReduction>
      <hardwareInterface>hardware_interface/PositionJointInterface</hardwareInterface>
    </actuator>
    <joint name="right_gripper/mimic_joint">
      <hardwareInterface>hardware_interface/PositionJointInterface</hardwareInterface>
    </joint>
  </transmission>
</robot>

